<?xml version="1.0" ?>
<!-- =================================================================================== -->
<!-- |    This document was autogenerated by xacro from tm12.urdf.xacro                | -->
<!-- |    EDITING THIS FILE BY HAND IS NOT RECOMMENDED                                 | -->
<!-- =================================================================================== -->
<robot name="tm12_with_gripper">
  <gazebo reference="link_1">
    <selfCollide>true</selfCollide>
  </gazebo>
  <gazebo reference="link_2">
    <selfCollide>true</selfCollide>
  </gazebo>
  <gazebo reference="link_3">
    <selfCollide>true</selfCollide>
  </gazebo>
  <gazebo reference="link_4">
    <selfCollide>true</selfCollide>
  </gazebo>
  <gazebo reference="link_5">
    <selfCollide>true</selfCollide>
  </gazebo>
  <gazebo reference="link_6">
    <selfCollide>true</selfCollide>
  </gazebo>
  <gazebo>
    <plugin filename="libgazebo_ros_control.so" name="gazebo_ros_control">
      <robotNamespace>/</robotNamespace>
      <robotSimType>gazebo_ros_control/DefaultRobotHWSim</robotSimType>
    </plugin>
  </gazebo>
  <transmission name="trans_1">
    <type>transmission_interface/SimpleTransmission</type>
    <joint name="joint_1">
      <hardwareInterface>hardware_interface/PositionJointInterface</hardwareInterface>
    </joint>
    <actuator name="motor_1">
      <mechanicalReduction>1</mechanicalReduction>
    </actuator>
  </transmission>
  <transmission name="trans_2">
    <type>transmission_interface/SimpleTransmission</type>
    <joint name="joint_2">
      <hardwareInterface>hardware_interface/PositionJointInterface</hardwareInterface>
    </joint>
    <actuator name="motor_2">
      <mechanicalReduction>1</mechanicalReduction>
    </actuator>
  </transmission>
  <transmission name="trans_3">
    <type>transmission_interface/SimpleTransmission</type>
    <joint name="joint_3">
      <hardwareInterface>hardware_interface/PositionJointInterface</hardwareInterface>
    </joint>
    <actuator name="motor_3">
      <mechanicalReduction>1</mechanicalReduction>
    </actuator>
  </transmission>
  <transmission name="trans_4">
    <type>transmission_interface/SimpleTransmission</type>
    <joint name="joint_4">
      <hardwareInterface>hardware_interface/PositionJointInterface</hardwareInterface>
    </joint>
    <actuator name="motor_4">
      <mechanicalReduction>1</mechanicalReduction>
    </actuator>
  </transmission>
  <transmission name="trans_5">
    <type>transmission_interface/SimpleTransmission</type>
    <joint name="joint_5">
      <hardwareInterface>hardware_interface/PositionJointInterface</hardwareInterface>
    </joint>
    <actuator name="motor_5">
      <mechanicalReduction>1</mechanicalReduction>
    </actuator>
  </transmission>
  <transmission name="trans_6">
    <type>transmission_interface/SimpleTransmission</type>
    <joint name="joint_6">
      <hardwareInterface>hardware_interface/PositionJointInterface</hardwareInterface>
    </joint>
    <actuator name="motor_6">
      <mechanicalReduction>1</mechanicalReduction>
    </actuator>
  </transmission>
  <material name="lightgrey">
    <color rgba="0.5 0.5 0.5 1.0"/>
  </material>
  <material name="grey">
    <color rgba="0.75 0.75 0.75 1.0"/>
  </material>
  <material name="white">
    <color rgba="0.95 0.95 0.95 1.0"/>
  </material>
  <material name="red">
    <color rgba="0.95 0.0 0.0 1.0"/>
  </material>
  <material name="orange">
    <color rgba="1.0 0.5 0.0 1.0"/>
  </material>
  <material name="yellow">
    <color rgba="1.0 1.0 0.0 1.0"/>
  </material>
  <material name="green">
    <color rgba="0.0 1.0 0.0 1.0"/>
  </material>
  <material name="blue">
    <color rgba="0.0 0.0 1.0 1.0"/>
  </material>
  <material name="indigo">
    <color rgba="0.3 0.3 0.6 1.0"/>
  </material>
  <material name="violet">
    <color rgba="0.6 0.0 1.0 1.0"/>
  </material>
  <material name="black">
    <color rgba="0.0 0.0 0.0 1.0"/>
  </material>
  <material name="darkolive">
    <color rgba="0.3 0.3 0.25 1.0"/>
  </material>
  <!--LinkDescription-->
  <link name="link_0">
    <visual>
      <geometry>
        <mesh filename="package://tm_description/meshes/tm12/visual/tm12-base.obj"/>
      </geometry>
      <material name="none"/>
    </visual>
    <collision>
      <geometry>
        <mesh filename="package://tm_description/meshes/tm12/collision/tm12-base_c.stl"/>
      </geometry>
    </collision>
    <inertial>
      <mass value="1.0"/>
      <origin rpy="0.000000 0.000000 0.000000" xyz="0.000000 0.000000 0.000000"/>
      <inertia ixx="0.00110833289" ixy="0.0" ixz="0.0" iyy="0.00110833289" iyz="0.0" izz="0.0018"/>
    </inertial>
  </link>
  <joint name="joint_1" type="revolute">
    <parent link="link_0"/>
    <child link="link_1"/>
    <origin rpy="0.000000 -0.000000 0.000000" xyz="0.000000 0.000000 0.165200"/>
    <axis xyz="0 0 1"/>
    <!--limit-->
    <limit effort="353" lower="-4.71238898038469" upper="4.71238898038469" velocity="2.0943951023931953"/>
    <dynamics damping="0.0" friction="0.0"/>
  </joint>
  <link name="link_1">
    <visual>
      <geometry>
        <mesh filename="package://tm_description/meshes/tm12/visual/tmr_750w_01.obj"/>
      </geometry>
      <material name="grey"/>
    </visual>
    <collision>
      <geometry>
        <mesh filename="package://tm_description/meshes/tm12/collision/tmr_750w_01_c.stl"/>
      </geometry>
    </collision>
    <inertial>
      <origin rpy="0.000000 0.000000 0.000000" xyz="0.000000 0.000000 0.000000"/>
      <mass value="7.6"/>
      <inertia ixx="0.020289334" ixy="0.000000" ixz="0.000000" iyy="0.020289334" iyz="0.000000" izz="0.021396270999999998"/>
    </inertial>
  </link>
  <joint name="joint_2" type="revolute">
    <parent link="link_1"/>
    <child link="link_2"/>
    <origin rpy="-1.570796 -1.570796 0.000000" xyz="0.000000 0.000000 0.000000"/>
    <axis xyz="0 0 1"/>
    <!--limit-->
    <limit effort="353" lower="-3.141592653589793" upper="3.141592653589793" velocity="2.0943951023931953"/>
    <dynamics damping="0.0" friction="0.0"/>
  </joint>
  <link name="link_2">
    <visual>
      <geometry>
        <mesh filename="package://tm_description/meshes/tm12/visual/tm12-arm1.obj"/>
      </geometry>
      <material name="lightgrey"/>
    </visual>
    <collision>
      <geometry>
        <mesh filename="package://tm_description/meshes/tm12/collision/tm12-arm1_c.stl"/>
      </geometry>
    </collision>
    <inertial>
      <origin rpy="0.000000 0.000000 0.000000" xyz="0.000000 0.000000 0.000000"/>
      <mass value="14.0239"/>
      <inertia ixx="0.071505715" ixy="0.000000" ixz="0.000000" iyy="1.1758788999999998" iyz="0.000000" izz="1.2033932999999999"/>
    </inertial>
  </link>
  <joint name="joint_3" type="revolute">
    <parent link="link_2"/>
    <child link="link_3"/>
    <origin rpy="0.000000 -0.000000 0.000000" xyz="0.636100 0.000000 0.000000"/>
    <axis xyz="0 0 1"/>
    <!--limit-->
    <limit effort="157" lower="-2.897246558310587" upper="2.897246558310587" velocity="3.141592653589793"/>
    <dynamics damping="0.0" friction="0.0"/>
  </joint>
  <link name="link_3">
    <visual>
      <geometry>
        <mesh filename="package://tm_description/meshes/tm12/visual/tm12-arm2.obj"/>
      </geometry>
      <material name="grey"/>
    </visual>
    <collision>
      <geometry>
        <mesh filename="package://tm_description/meshes/tm12/collision/tm12-arm2_c.stl"/>
      </geometry>
    </collision>
    <inertial>
      <origin rpy="0.000000 0.000000 0.000000" xyz="0.000000 0.000000 0.000000"/>
      <mass value="3.3577"/>
      <inertia ixx="0.009755469" ixy="0.000000" ixz="0.000000" iyy="0.16334719" iyz="0.000000" izz="0.16656678"/>
    </inertial>
  </link>
  <joint name="joint_4" type="revolute">
    <parent link="link_3"/>
    <child link="link_4"/>
    <origin rpy="0.000000 -0.000000 1.570796" xyz="0.557900 0.000000 -0.156300"/>
    <axis xyz="0 0 1"/>
    <!--limit-->
    <limit effort="54" lower="-3.141592653589793" upper="3.141592653589793" velocity="3.141592653589793"/>
    <dynamics damping="0.0" friction="0.0"/>
  </joint>
  <link name="link_4">
    <visual>
      <geometry>
        <mesh filename="package://tm_description/meshes/tm5-900/visual/tmr_100w_01.obj"/>
      </geometry>
      <material name="lightgrey"/>
    </visual>
    <collision>
      <geometry>
        <mesh filename="package://tm_description/meshes/tm5-900/collision/tmr_100w_01_c.stl"/>
      </geometry>
    </collision>
    <inertial>
      <origin rpy="0.000000 0.000000 0.000000" xyz="0.000000 0.000000 0.000000"/>
      <mass value="1.576"/>
      <inertia ixx="0.002058405" ixy="0.000000" ixz="0.000000" iyy="0.0025630790000000002" iyz="0.000000" izz="0.00264321"/>
    </inertial>
  </link>
  <joint name="joint_5" type="revolute">
    <parent link="link_4"/>
    <child link="link_5"/>
    <origin rpy="1.570796 -0.000000 0.000000" xyz="0.000000 -0.106000 0.000000"/>
    <axis xyz="0 0 1"/>
    <!--limit-->
    <limit effort="54" lower="-3.141592653589793" upper="3.141592653589793" velocity="3.141592653589793"/>
    <dynamics damping="0.0" friction="0.0"/>
  </joint>
  <link name="link_5">
    <visual>
      <geometry>
        <mesh filename="package://tm_description/meshes/tm5-900/visual/tmr_100w_02.obj"/>
      </geometry>
      <material name="lightgrey"/>
    </visual>
    <collision>
      <geometry>
        <mesh filename="package://tm_description/meshes/tm5-900/collision/tmr_100w_02_c.stl"/>
      </geometry>
    </collision>
    <inertial>
      <origin rpy="0.000000 0.000000 0.000000" xyz="0.000000 0.000000 0.000000"/>
      <mass value="1.576"/>
      <inertia ixx="0.002058405" ixy="0.000000" ixz="0.000000" iyy="0.0025630790000000002" iyz="0.000000" izz="0.00264321"/>
    </inertial>
  </link>
  <joint name="joint_6" type="revolute">
    <parent link="link_5"/>
    <child link="link_6"/>
    <origin rpy="1.570796 -0.000000 0.000000" xyz="0.000000 -0.113150 0.000000"/>
    <axis xyz="0 0 1"/>
    <!--limit-->
    <limit effort="54" lower="-4.71238898038469" upper="4.71238898038469" velocity="3.141592653589793"/>
    <dynamics damping="0.0" friction="0.0"/>
  </joint>
  <link name="link_6">
    <visual>
      <geometry>
        <mesh filename="package://tm_description/meshes/tm5-900/visual/tmr_ee.obj"/>
      </geometry>
      <material name="grey"/>
    </visual>
    <collision>
      <geometry>
        <mesh filename="package://tm_description/meshes/tm5-900/collision/tmr_ee_c.stl"/>
      </geometry>
    </collision>
    <inertial>
      <origin rpy="0.000000 0.000000 0.000000" xyz="0.000000 0.000000 0.000000"/>
      <mass value="0.65"/>
      <inertia ixx="0.000774544" ixy="0.000000" ixz="0.000000" iyy="0.001383811" iyz="0.000000" izz="0.001559496"/>
    </inertial>
  </link>
  <link name="base"/>
  <joint name="base_fixed_joint" type="fixed">
    <parent link="base"/>
    <child link="link_0"/>
    <origin rpy="0.000000 0.000000 0.000000" xyz="0.000000 0.000000 0.000000"/>
  </joint>
  <link name="flange"/>
  <joint name="flange_fixed_joint" type="fixed">
    <parent link="link_6"/>
    <child link="flange"/>
    <origin rpy="0.000000 0.000000 0.000000" xyz="0.000000 0.000000 0.000000"/>
  </joint>
  <!--LinkDescription-->

  <!--new created joint for combining arm and gripper-->
  <joint
    name="arm_combine_gripper"
    type="fixed">
    <origin
      xyz="0 0 0"
      rpy="0 0 0" />
    <parent
      link="link_6" />
    <child
      link="robotiq_85_base_link" />
    <axis
      xyz="0 0 0" />
  </joint>

  <!--gripper-->
  <link
    name="robotiq_85_base_link">
    <inertial>
      <origin
        xyz="0.00021987 -2.3546E-10 0.030163"
        rpy="0 0 0" />
      <mass
        value="0.30915" />
      <inertia
        ixx="0.00028972"
        ixy="-5.7879E-10"
        ixz="-1.8543E-06"
        iyy="0.00030737"
        iyz="1.682E-12"
        izz="0.00019914" />
    </inertial>
    <visual>
      <origin
        xyz="0 0 0"
        rpy="0 0 0" />
      <geometry>
        <mesh
          filename="package://robotiq_arg85_description/meshes/robotiq_85_base_link_fine.STL" />
      </geometry>
      <material
        name="">
        <color
          rgba="0.1 0.1 0.1 1" />
      </material>
    </visual>
    <collision>
      <origin
        xyz="0 0 0"
        rpy="0 0 0" />
      <geometry>
        <mesh
          filename="package://robotiq_arg85_description/meshes/robotiq_85_base_link_coarse.STL" />
      </geometry>
    </collision>
  </link>
  <link
    name="left_outer_knuckle">
    <inertial>
      <origin
        xyz="0.0178331863169983 3.68915177224286E-11 0.0021442477325704"
        rpy="0 0 0" />
      <mass
        value="0.00684838849434396" />
      <inertia
        ixx="2.66832029033166E-07"
        ixy="1.66142314639824E-15"
        ixz="1.45945633322873E-07"
        iyy="1.3889233257419E-06"
        iyz="2.82951161241588E-15"
        izz="1.26603336914415E-06" />
    </inertial>
    <visual>
      <origin
        xyz="0 0 0"
        rpy="0 0 0" />
      <geometry>
        <mesh
          filename="package://tm_description/meshes/gripper/outer_knuckle_fine.STL" />
      </geometry>
      <material
        name="">
        <color
          rgba="0.1 0.1 0.1 1" />
      </material>
    </visual>
    <collision>
      <origin
        xyz="0 0 0"
        rpy="0 0 0" />
      <geometry>
        <mesh
          filename="package://tm_description/meshes/gripper/outer_knuckle_coarse.STL" />
      </geometry>
    </collision>
  </link>
  <joint
    name="finger_joint"
    type="revolute">
    <origin
      xyz="0.0306011444260539 0 0.0627920162695395"
      rpy="0 0 0" />
    <parent
      link="robotiq_85_base_link" />
    <child
      link="left_outer_knuckle" />
    <axis
      xyz="0 -1 0" />
    <limit
	  lower="0"
      upper="0.725"
      velocity="2.0"
      effort="1000" />
  </joint>
  <link
    name="left_outer_finger">
    <inertial>
      <origin
        xyz="0.00131451599174296 2.88942057994543E-15 0.0215404163180413"
        rpy="0 0 0" />
      <mass
        value="0.0273093985570947" />
      <inertia
        ixx="8.51629628283022E-06"
        ixy="2.58174336207405E-19"
        ixz="3.83829504344079E-07"
        iyy="6.9133328065108E-06"
        iyz="-7.58589926143789E-19"
        izz="2.25006832221981E-06" />
    </inertial>
    <visual>
      <origin
        xyz="0 0 0"
        rpy="0 0 0" />
      <geometry>
        <mesh
          filename="package://tm_description/meshes/gripper/outer_finger_fine.STL" />
      </geometry>
      <material
        name="">
        <color
          rgba="0.1 0.1 0.1 1" />
      </material>
    </visual>
    <collision>
      <origin
        xyz="0 0 0"
        rpy="0 0 0" />
      <geometry>
        <mesh
          filename="package://tm_description/meshes/gripper/outer_finger_coarse.STL" />
      </geometry>
    </collision>
  </link>
  <joint
    name="left_outer_finger_joint"
    type="fixed">
    <origin
      xyz="0.0316910442266543 0 -0.00193396375724605"
      rpy="0 0 0" />
    <parent
      link="left_outer_knuckle" />
    <child
      link="left_outer_finger" />
    <axis
      xyz="0 -1 0" />
  </joint>
  <link
    name="left_inner_knuckle">
    <inertial>
      <origin
        xyz="0.017097546626628 -3.93808524389535E-10 0.0224918438201868"
        rpy="0 0 0" />
      <mass
        value="0.0110930853895903" />
      <inertia
        ixx="4.23392770691541E-06"
        ixy="5.748978936968E-15"
        ixz="1.78855677119788E-06"
        iyy="3.96548790524392E-06"
        iyz="1.05464666369669E-14"
        izz="3.24068002883007E-06" />
    </inertial>
    <visual>
      <origin
        xyz="0 0 0"
        rpy="0 0 0" />
      <geometry>
        <mesh
          filename="package://tm_description/meshes/gripper/inner_knuckle_fine.STL" />
      </geometry>
      <material
        name="">
        <color
          rgba="0.1 0.1 0.1 1" />
      </material>
    </visual>
    <collision>
      <origin
        xyz="0 0 0"
        rpy="0 0 0" />
      <geometry>
        <mesh
          filename="package://tm_description/meshes/gripper/inner_knuckle_coarse.STL" />
      </geometry>
    </collision>
  </link>
  <joint
    name="left_inner_knuckle_joint"
    type="revolute">
    <origin
      xyz="0.0127000000001501 0 0.0693074999999639"
      rpy="0 0 0" />
    <parent
      link="robotiq_85_base_link" />
    <child
      link="left_inner_knuckle" />
    <axis
      xyz="0 -1 0" />
    <limit
      lower="0"
      upper="0.8757"
      velocity="2.0"
      effort="1000" />
    <mimic 
      joint="finger_joint"
      multiplier="1"
      offset="0" />
  </joint>
  <link
    name="left_inner_finger">
    <inertial>
      <origin
        xyz="0.0060275613594574 -6.29183141465421E-15 0.00669925693133241"
        rpy="0 0 0" />
      <mass
        value="0.00724255346165745" />
      <inertia
        ixx="1.47824274053603E-06"
        ixy="-3.94884463570303E-19"
        ixz="-3.45268847648622E-07"
        iyy="1.70064480838395E-06"
        iyz="3.5059838910097E-19"
        izz="4.77151336838364E-07" />
    </inertial>
    <visual>
      <origin
        xyz="0 0 0"
        rpy="0 0 0" />
      <geometry>
        <mesh
          filename="package://tm_description/meshes/gripper/inner_finger_fine.STL" />
      </geometry>
      <material
        name="">
        <color
          rgba="0.1 0.1 0.1 1" />
      </material>
    </visual>
    <collision>
      <origin
        xyz="0 0 0"
        rpy="0 0 0" />
      <geometry>
        <mesh
          filename="package://tm_description/meshes/gripper/inner_finger_coarse.STL" />
      </geometry>
    </collision>
  </link>
  <joint
    name="left_inner_finger_joint"
    type="revolute">
    <origin
      xyz="0.034585310861294 0 0.0454970193817975"
      rpy="0 0 0" />
    <parent
      link="left_inner_knuckle" />
    <child
      link="left_inner_finger" />
    <axis
      xyz="0 -1 0" />
    <limit
      lower="0"
      upper="0.8757"
      velocity="2.0"
      effort="1000" />
    <mimic 
      joint="finger_joint"
      multiplier="-1"
      offset="0" />
  </joint>
  <link
    name="right_inner_knuckle">
    <inertial>
      <origin
        xyz="0.0168606186773776 3.93808471820465E-10 0.0226699950793434"
        rpy="0 0 0" />
      <mass
        value="0.0110930853895903" />
      <inertia
        ixx="4.27134775939882E-06"
        ixy="-8.53568456728898E-15"
        ixz="1.77774229944246E-06"
        iyy="3.96548790524392E-06"
        iyz="-8.45108024914164E-15"
        izz="3.20325997634666E-06" />
    </inertial>
    <visual>
      <origin
        xyz="0 0 0"
        rpy="0 0 0" />
      <geometry>
        <mesh
          filename="package://tm_description/meshes/gripper/inner_knuckle_fine.STL" />
      </geometry>
      <material
        name="">
        <color
          rgba="0.1 0.1 0.1 1" />
      </material>
    </visual>
    <collision>
      <origin
        xyz="0 0 0"
        rpy="0 0 0" />
      <geometry>
        <mesh
          filename="package://tm_description/meshes/gripper/inner_knuckle_coarse.STL" />
      </geometry>
    </collision>
  </link>
  <joint
    name="right_inner_knuckle_joint"
    type="revolute">
    <origin
      xyz="-0.0126999999998499 0 0.0693075000000361"
      rpy="0 0 3.14159265358979" />
    <parent
      link="robotiq_85_base_link" />
    <child
      link="right_inner_knuckle" />
    <axis
      xyz="0 1 0" />
    <limit
      lower="0"
      upper="0.8757"
      velocity="2.0"
      effort="1000" />
    <mimic 
      joint="finger_joint"
      multiplier="-1"
      offset="0" />
  </joint>
  <link
    name="right_inner_finger">
    <inertial>
      <origin
        xyz="0.00602756228812038 -6.47284509480176E-15 0.00669925609578108"
        rpy="0 0 0" />
      <mass
        value="0.00724255346165744" />
      <inertia
        ixx="1.47824283625957E-06"
        ixy="-3.95952064019123E-19"
        ixz="-3.45268708875543E-07"
        iyy="1.70064480838394E-06"
        iyz="3.55286507960029E-19"
        izz="4.77151241114822E-07" />
    </inertial>
    <visual>
      <origin
        xyz="0 0 0"
        rpy="0 0 0" />
      <geometry>
        <mesh
          filename="package://tm_description/meshes/gripper/inner_finger_fine.STL" />
      </geometry>
      <material
        name="">
        <color
          rgba="0.1 0.1 0.1 1" />
      </material>
    </visual>
    <collision>
      <origin
        xyz="0 0 0"
        rpy="0 0 0" />
      <geometry>
        <mesh
          filename="package://tm_description/meshes/gripper/inner_finger_coarse.STL" />
      </geometry>
    </collision>
  </link>
  <joint
    name="right_inner_finger_joint"
    type="revolute">
    <origin
      xyz="0.0341060475457406 0 0.0458573878541688"
      rpy="0 0 0" />
    <parent
      link="right_inner_knuckle" />
    <child
      link="right_inner_finger" />
    <axis
      xyz="0 1 0" />
    <limit
      lower="0"
      upper="0.8757"
      velocity="2.0"
      effort="1000" />
    <mimic 
      joint="finger_joint"
      multiplier="1"
      offset="0" />
  </joint>
  <link
    name="right_outer_knuckle">
    <inertial>
      <origin
        xyz="0.0178097074051638 3.60493211424024E-11 0.00233123458346721"
        rpy="0 0 0" />
      <mass
        value="0.00684838849401352" />
      <inertia
        ixx="2.70004361573169E-07"
        ixy="1.59579467624491E-15"
        ixz="1.56396493788199E-07"
        iyy="1.38892332558312E-06"
        iyz="2.82357800318817E-15"
        izz="1.26286103637978E-06" />
    </inertial>
    <visual>
      <origin
        xyz="0 0 0"
        rpy="0 0 0" />
      <geometry>
        <mesh
          filename="package://tm_description/meshes/gripper/outer_knuckle_fine.STL" />
      </geometry>
      <material
        name="">
        <color
          rgba="0.1 0.1 0.1 1" />
      </material>
    </visual>
    <collision>
      <origin
        xyz="0 0 0"
        rpy="0 0 0" />
      <geometry>
        <mesh
          filename="package://tm_description/meshes/gripper/outer_knuckle_coarse.STL" />
      </geometry>
    </collision>
  </link>
  <joint
    name="right_outer_knuckle_joint"
    type="revolute">
    <origin
      xyz="-0.0306011444258893 0 0.0627920162695395"
      rpy="0 0 3.14159265358979" />
    <parent
      link="robotiq_85_base_link" />
    <child
      link="right_outer_knuckle" />
    <axis
      xyz="0 1 0" />
    <limit
      lower="0"
      upper="0.8757"
      velocity="2.0"
      effort="1000" />
    <mimic 
      joint="finger_joint"
      multiplier="-1"
      offset="0" />
  </joint>
  <link
    name="right_outer_finger">
    <inertial>
      <origin
        xyz="0.00108844269639009 -2.611488350845E-15 0.0215530225245502"
        rpy="0 0 0" />
      <mass
        value="0.0273093985570947" />
      <inertia
        ixx="8.52366028592721E-06"
        ixy="3.41683380899422E-19"
        ixz="3.18003675694284E-07"
        iyy="6.91333280651081E-06"
        iyz="7.37726682706417E-19"
        izz="2.24270431912283E-06" />
    </inertial>
    <visual>
      <origin
        xyz="0 0 0"
        rpy="0 0 0" />
      <geometry>
        <mesh
          filename="package://tm_description/meshes/gripper/outer_finger_fine.STL" />
      </geometry>
      <material
        name="">
        <color
          rgba="0.1 0.1 0.1 1" />
      </material>
    </visual>
    <collision>
      <origin
        xyz="0 0 0"
        rpy="0 0 0" />
      <geometry>
        <mesh
          filename="package://tm_description/meshes/gripper/outer_finger_coarse.STL" />
      </geometry>
    </collision>
  </link>
  <joint
    name="right_outer_finger_joint"
    type="fixed">
    <origin
      xyz="0.0317095909367246 0 -0.0016013564954687"
      rpy="0 0 0" />
    <parent
      link="right_outer_knuckle" />
    <child
      link="right_outer_finger" />
    <axis
      xyz="0 1 0" />
  </joint>
</robot>
